/*
 Program which includes try and catch block that processes the
ArithmeticException generated by the division-by-zero error.
 */
package lab4;

public class q1 {
    public static void main(String args[]) {
        int num=9, rel=0;
        try {
            rel= num /0;
            System.out.println("this statement will not be executed");
            
        }catch(ArithmeticException e){
            System.out.println("Divide by Zero occurred");
        }
        System.out.println("after catch block");
    }
}
